<?xml version="1.0"?>
<sdf version="1.4">
    <model name="simple_gripper">
        <link name="left_riser">
            <pose>0 -0.2 0.25 0 0 0</pose>
            <inertial>
                <pose>0 0 -0.25 0 0 0</pose>
                <inertia>
                    <ixx>0.01</ixx>
                    <ixy>0</ixy>
                    <ixz>0</ixz>
                    <iyy>0.01</iyy>
                    <iyz>0</iyz>
                    <izz>0.01</izz>
                </inertia>
                <mass>0.5</mass>
            </inertial>
            <collision name="collision">
                <geometry>
                    <box>
                        <size>0.1 0.1 1.0</size>
                    </box>
                </geometry>
            </collision>
            <visual name="visual">
                <geometry>
                    <box>
                        <size>0.1 0.1 1.0</size>
                    </box>
                </geometry>
                <material>
                    <script>Gazebo/Purple</script>
                </material>
            </visual>
        </link>
        <link name="right_riser">
            <pose>0 0.2 0.25 0 0 0</pose>
            <inertial>
                <pose>0 0 -0.25 0 0 0</pose>
                <inertia>
                    <ixx>0.01</ixx>
                    <ixy>0</ixy>
                    <ixz>0</ixz>
                    <iyy>0.01</iyy>
                    <iyz>0</iyz>
                    <izz>0.01</izz>
                </inertia>
                <mass>0.5</mass>
            </inertial>
            <collision name="collision">
                <geometry>
                    <box>
                        <size>0.1 0.1 1.0</size>
                    </box>
                </geometry>
            </collision>
            <visual name="visual">
                <geometry>
                    <box>
                        <size>0.1 0.1 1.0</size>
                    </box>
                </geometry>
                <material>
                    <script>Gazebo/Purple</script>
                </material>
            </visual>
        </link>
        <link name="palm">
            <pose>0.0 0.0 0.05 0 0 0</pose>
            <inertial>
                <inertia>
                    <ixx>0.01</ixx>
                    <ixy>0</ixy>
                    <ixz>0</ixz>
                    <iyy>0.01</iyy>
                    <iyz>0</iyz>
                    <izz>0.01</izz>
                </inertia>
                <mass>0.04</mass>
            </inertial>
            <collision name="collision">
                <geometry>
                    <box>
                        <size>0.1 0.3 0.1</size>
                    </box>
                </geometry>
            </collision>
            <visual name="visual">
                <geometry>
                    <box>
                        <size>0.1 0.3 0.1</size>
                    </box>
                </geometry>
                <material>
                    <script>Gazebo/Red</script>
                </material>
            </visual>
        </link>
        <link name="left_finger">
            <pose>0.15 -0.025 0.05 0 0 0</pose>
            <inertial>
                <inertia>
                    <ixx>0.01</ixx>
                    <ixy>0</ixy>
                    <ixz>0</ixz>
                    <iyy>0.01</iyy>
                    <iyz>0</iyz>
                    <izz>0.01</izz>
                </inertia>
                <mass>0.005</mass>
            </inertial>
            <collision name="collision">
                <geometry>
                    <box>
                        <size>0.2 0.05 0.1</size>
                    </box>
                </geometry>
            </collision>
            <visual name="visual">
                <geometry>
                    <box>
                        <size>0.2 0.05 0.1</size>
                    </box>
                </geometry>
                <material>
                    <script>Gazebo/Blue</script>
                </material>
            </visual>
        </link>
        <link name="right_finger">
            <pose>0.15 0.025 0.05 0 0 0</pose>
            <inertial>
                <inertia>
                    <ixx>0.01</ixx>
                    <ixy>0</ixy>
                    <ixz>0</ixz>
                    <iyy>0.01</iyy>
                    <iyz>0</iyz>
                    <izz>0.01</izz>
                </inertia>
                <mass>0.005</mass>
            </inertial>
            <collision name="collision">
                <geometry>
                    <box>
                        <size>0.2 0.05 0.1</size>
                    </box>
                </geometry>
            </collision>
            <visual name="visual">
                <geometry>
                    <box>
                        <size>0.2 0.05 0.1</size>
                    </box>
                </geometry>
                <material>
                    <script>Gazebo/Blue</script>
                </material>
            </visual>
        </link>
        <joint name="palm_right_riser" type="prismatic">
            <child>palm</child>
            <parent>right_riser</parent>
            <axis>
                <limit>
                    <lower>-0.25</lower>
                    <upper>0.65</upper>
                </limit>
                <xyz>0 0 1</xyz>
            </axis>
        </joint>
        <joint name="palm_left_riser" type="prismatic">
            <child>palm</child>
            <parent>left_riser</parent>
            <axis>
                <limit>
                    <lower>-0.25</lower>
                    <upper>0.65</upper>
                </limit>
                <xyz>0 0 1</xyz>
            </axis>
        </joint>
        <joint name="left_finger_palm" type="prismatic">
            <child>left_finger</child>
            <parent>palm</parent>
            <axis>
                <limit>
                    <lower>0</lower>
                    <upper>0.1</upper>
                </limit>
                <xyz>0 -1 0</xyz>
            </axis>
        </joint>
        <joint name="right_finger_palm" type="prismatic">
            <child>right_finger</child>
            <parent>palm</parent>
            <axis>
                <limit>
                    <lower>0</lower>
                    <upper>0.1</upper>
                </limit>
                <xyz>0 1 0</xyz>
            </axis>
        </joint>
    </model>
</sdf>
